<?xml version="1.0" ?>
<!--
    dg5f_right.urdf
    Licensed under the BSD-3-Clause
    Copyright (c) 2025 Tesollo Inc.
    See LICENSE file for details.

    Reference:
    * https://tesollo.com/dg-5f/
-->

<robot name="dg5f_right">
  <link name="world"/>

  <joint name="rotate_y_neg90" type="fixed">
    <parent link="world"/>
    <child link="rl_dg_mount"/>
    <origin rpy="0 1.5708 0" xyz="0 0 0"/>
  </joint>
  
  <link name="rl_dg_mount">
    <inertial>
      <origin xyz="-6.4721E-09 -2.1674E-05 0.0049997" rpy="0.0 0.0 0.0" />
      <inertia ixx="1.0999E-05" ixy="-2.1734E-12" ixz="1.2441E-12" iyy="1.1018E-05" iyz="4.0435E-09" izz="2.0531E-05" />
      <mass value="0.05" />
    </inertial>
    <visual>
      <geometry>
        <mesh filename="./meshes/rl_dg_mount.dae"/>
      </geometry>
    </visual>
    <collision>
      <geometry>
        <mesh filename="./meshes/rl_dg_mount_c.STL"/>
      </geometry>
    </collision>
  </link>

  <link name="rl_dg_base">
    <inertial>
      <origin xyz="-0.00058969 0.0005138 0.037363" rpy="0.0 0.0 0.0" />
      <inertia ixx="0.00048608" ixy="1.041E-05" ixz="1.7229E-05" iyy="0.00049085" iyz="-5.1908E-06" izz="0.00043369" />
      <mass value="0.45" />
    </inertial>
    <visual>
      <origin xyz="0 0 0" rpy="0 0 0" />
      <geometry>
        <mesh filename="./meshes/rl_dg_base.dae" />
      </geometry>
    </visual>
    <collision>
      <origin xyz="0 0 0" rpy="0 0 0" />
      <geometry>
        <mesh filename="./meshes/rl_dg_base_c.STL" />
      </geometry>
    </collision>
  </link>
  <joint name="rj_dg_base" type="fixed">
    <parent link="rl_dg_mount"/>
    <child link="rl_dg_base"/>
    <origin rpy="0 0 0" xyz="0 0 0.004"/>
  </joint>

  <link name="rl_dg_palm">
    <inertial>
      <origin xyz="-0.0089577 0.00095577 0.041325" rpy="0.0 0.0 0.0" />
      <inertia ixx="0.00052656" ixy="2.513E-06" ixz="-2.2304E-05" iyy="0.00041654" iyz="-4.8956E-05" izz="0.00045783" />
      <mass value="0.35" />
    </inertial>
    <visual>
      <origin xyz="0 0 0" rpy="0 0 0" />
      <geometry>
        <mesh filename="./meshes/rl_dg_palm.dae" />
      </geometry>
    </visual>
    <collision>
      <origin xyz="0 0 0" rpy="0 0 0" />
      <geometry>
        <mesh filename="./meshes/rl_dg_palm_c.STL" />
      </geometry>
    </collision>
  </link>
  <joint name="rj_dg_palm" type="fixed">
    <parent link="rl_dg_base"/>
    <child link="rl_dg_palm"/>
    <origin rpy="0 0 0" xyz="0 0 0.0698"/>
  </joint>

  <link name="rl_dg_1_1">
    <inertial>
      <origin xyz="0.021473 3.1163E-06 0.0028146" rpy="0.0 0.0 0.0" />
      <inertia ixx="4.2707E-06" ixy="2.4123E-09" ixz="2.9055E-06" iyy="1.3718E-05" iyz="-1.3824E-09" izz="1.2161E-05" />
      <mass value="0.045" />
    </inertial>
    <visual>
      <origin xyz="0 0 0" rpy="0 0 0" />
      <geometry>
        <mesh filename="./meshes/rl_dg_1_1.dae" />
      </geometry>
    </visual>
    <collision>
      <origin xyz="0 0 0" rpy="0 0 0" />
      <geometry>
        <mesh filename="./meshes/rl_dg_1_1_c.STL" />
      </geometry>
    </collision>
  </link>
  <joint name="rj_dg_1_1" type="revolute">
    <origin xyz="-0.0162 0.019 0.0128" rpy="0.0 0.0 0.0" />
    <parent link="rl_dg_palm" />
    <child link="rl_dg_1_1" />
    <axis xyz="1 0 0" />
    <limit lower="-0.3839724354387525" upper="0.8901179185171081" effort="7.5" velocity="3.141592653589793"/>
  </joint>

  <link name="rl_dg_1_2">
    <inertial>
      <origin xyz="0.00055633 0.0155 0.00055633" rpy="0.0 0.0 0.0" />
      <inertia ixx="1.9935E-06" ixy="-1.5774E-07" ixz="3.114E-09" iyy="1.459E-06" iyz="1.5774E-07" izz="1.9935E-06" />
      <mass value="0.025" />
    </inertial>
    <visual>
      <origin xyz="0 0 0" rpy="0 0 0" />
      <geometry>
        <mesh filename="./meshes/rl_dg_1_2.dae" />
      </geometry>
    </visual>
    <collision>
      <origin xyz="0 0 0" rpy="0 0 0" />
      <geometry>
        <mesh filename="./meshes/rl_dg_1_2_c.STL" />
      </geometry>
    </collision>
  </link>
  <joint name="rj_dg_1_2" type="revolute">
    <origin xyz="0.04195 0.0 0.0" rpy="0.0 0.0 0.0" />
    <parent link="rl_dg_1_1" />
    <child link="rl_dg_1_2" />
    <axis xyz="0 0 1" />
    <limit lower="-3.141592653589793" upper="0.0" effort="7.5" velocity="3.141592653589793"/>
  </joint>

  <link name="rl_dg_1_3">
    <inertial>
      <origin xyz="2.3008E-05 0.014842 4.7446E-06" rpy="0.0 0.0 0.0" />
      <inertia ixx="5.9794E-06" ixy="-3.6014E-07" ixz="-1.3678E-09" iyy="2.458E-06" iyz="-2.3552E-09" izz="6.4181E-06" />
      <mass value="0.045" />
    </inertial>
    <visual>
      <origin xyz="0 0 0" rpy="0 0 0" />
      <geometry>
        <mesh filename="./meshes/rl_dg_1_3.dae" />
      </geometry>
    </visual>
    <collision>
      <origin xyz="0 0 0" rpy="0 0 0" />
      <geometry>
        <mesh filename="./meshes/rl_dg_1_3_c.STL" />
      </geometry>
    </collision>
  </link>
  <joint name="rj_dg_1_3" type="revolute">
    <origin xyz="0.0 0.031 0.0" rpy="0.0 0.0 0.0" />
    <parent link="rl_dg_1_2" />
    <child link="rl_dg_1_3" />
    <axis xyz="1 0 0" />
    <limit lower="-0.1" upper="1.5707963267948966" effort="7.5" velocity="3.141592653589793"/>
  </joint>

  <link name="rl_dg_1_4">
    <inertial>
      <origin xyz="-0.00020482 0.018795 -0.00036539" rpy="0.0 0.0 0.0" />
      <inertia ixx="9.4915E-06" ixy="-1.5157E-07" ixz="3.4626E-09" iyy="2.9391E-06" iyz="3.7813E-07" izz="9.8194E-06" />
      <mass value="0.045" />
    </inertial>
    <visual>
      <origin xyz="0 0 0" rpy="0 0 0" />
      <geometry>
        <mesh filename="./meshes/rl_dg_1_4.dae" />
      </geometry>
    </visual>
    <collision>
      <origin xyz="0 0 0" rpy="0 0 0" />
      <geometry>
        <mesh filename="./meshes/rl_dg_1_4_c.STL" />
      </geometry>
    </collision>
  </link>
  <joint name="rj_dg_1_4" type="revolute">
    <origin xyz="0.0 0.0388 0.0" rpy="0.0 0.0 0.0" />
    <parent link="rl_dg_1_3" />
    <child link="rl_dg_1_4" />
    <axis xyz="1 0 0" />
    <limit lower="-0.1" upper="1.5707963267948966" effort="7.5" velocity="3.141592653589793"/>
  </joint>

  <link name="rl_dg_1_tip">
    <inertial>
      <origin xyz="5.479E-07 0.007157 0.0038063" rpy="0.0 0.0 0.0" />
      <inertia ixx="1.9895E-07" ixy="-3.0731E-11" ixz="2.1191E-12" iyy="2.5698E-07" iyz="1.3375E-08" izz="3.2445E-07" />
      <mass value="0.005" />
    </inertial>
    <visual>
      <origin xyz="0 0 0" rpy="0 0 0" />
      <geometry>
        <mesh filename="./meshes/rl_dg_1_tip.dae" />
      </geometry>
    </visual>
    <collision>
      <origin xyz="0 0 0" rpy="0 0 0" />
      <geometry>
        <mesh filename="./meshes/rl_dg_1_tip_c.STL" />
      </geometry>
    </collision>
  </link>
  <joint name="rj_dg_1_tip" type="fixed">
    <origin xyz="0.0 0.0363 0.0" rpy="0.0 0.0 0.0" />
    <parent link="rl_dg_1_4" />
    <child link="rl_dg_1_tip" />
  </joint>
</robot>
